<?xml version="1.0" encoding="utf-8"?>
<!-- =================================================================================== -->
<!-- |    This document was autogenerated by xacro from vx300s_gripper.urdf.xacro      | -->
<!-- |    EDITING THIS FILE BY HAND IS NOT RECOMMENDED                                 | -->
<!-- =================================================================================== -->
<robot name="vx300s_gripper">
  <material name="interbotix_black">
    <texture filename="package://interbotix_descriptions/meshes/interbotix_black.png"/>
  </material>
  <link name="/base_link">
    <visual>
      <origin rpy="0 0 1.57079632679" xyz="0 0 0"/>
      <geometry>
        <mesh filename="package://interbotix_descriptions/meshes/meshes_vx300s/VXSA-300-M-1-Base.stl" scale="0.001 0.001 0.001"/>
      </geometry>
      <material name="interbotix_black"/>
    </visual>
    <collision>
      <origin rpy="0 0 1.57079632679" xyz="0 0 0"/>
      <geometry>
        <mesh filename="package://interbotix_descriptions/meshes/meshes_vx300s/VXSA-300-M-1-Base.stl" scale="0.001 0.001 0.001"/>
      </geometry>
    </collision>
    <inertial>
      <origin rpy="0 0 1.57079632679" xyz="-0.0534774000 -0.0005625750 0.0205961000"/>
      <mass value="0.969034"/>
      <inertia ixx="0.0060240000" ixy="0.0000471300" ixz="0.0000038510" iyy="0.0017000000" iyz="-0.0000841500" izz="0.0071620000"/>
    </inertial>
  </link>
  <joint name="waist" type="revolute">
    <axis xyz="0 0 1"/>
    <limit effort="100" lower="-3.14159265359" upper="3.14159265359" velocity="3.14159265359"/>
    <origin rpy="0 0 0" xyz="0 0 0.0787"/>
    <parent link="/base_link"/>
    <child link="/shoulder_link"/>
  </joint>
  <transmission name="trans_waist">
    <type>transmission_interface/SimpleTransmission</type>
    <joint name="waist">
      <hardwareInterface>hardware_interface/EffortJointInterface</hardwareInterface>
    </joint>
    <actuator name="waist_motor">
      <mechanicalReduction>1</mechanicalReduction>
    </actuator>
  </transmission>
  <link name="/shoulder_link">
    <visual>
      <origin rpy="0 0 1.57079632679" xyz="0 0 -0.003"/>
      <geometry>
        <mesh filename="package://interbotix_descriptions/meshes/meshes_vx300s/VXSA-300-M-2-Shoulder.stl" scale="0.001 0.001 0.001"/>
      </geometry>
      <material name="interbotix_black"/>
    </visual>
    <collision>
      <origin rpy="0 0 1.57079632679" xyz="0 0 -0.003"/>
      <geometry>
        <mesh filename="package://interbotix_descriptions/meshes/meshes_vx300s/VXSA-300-M-2-Shoulder.stl" scale="0.001 0.001 0.001"/>
      </geometry>
    </collision>
    <inertial>
      <origin rpy="0 0 1.57079632679" xyz="0.0002592330 -0.0000033552 0.0116129000"/>
      <mass value="0.798614"/>
      <inertia ixx="0.0009388000" ixy="-0.0000000010" ixz="-0.0000000191" iyy="0.0011380000" iyz="0.0000059568" izz="0.0012010000"/>
    </inertial>
  </link>
  <joint name="shoulder" type="revolute">
    <axis xyz="0 1 0"/>
    <limit effort="100" lower="-1.85004900711" upper="1.76278254451" velocity="3.14159265359"/>
    <origin rpy="0 0 0" xyz="0 0 0.04805"/>
    <parent link="/shoulder_link"/>
    <child link="/upper_arm_link"/>
  </joint>
  <transmission name="trans_shoulder">
    <type>transmission_interface/SimpleTransmission</type>
    <joint name="shoulder">
      <hardwareInterface>hardware_interface/EffortJointInterface</hardwareInterface>
    </joint>
    <actuator name="shoulder_motor">
      <mechanicalReduction>1</mechanicalReduction>
    </actuator>
  </transmission>
  <link name="/upper_arm_link">
    <visual>
      <origin rpy="0 0 1.57079632679" xyz="0 0 0"/>
      <geometry>
        <mesh filename="package://interbotix_descriptions/meshes/meshes_vx300s/VXSA-300-M-3-UA.stl" scale="0.001 0.001 0.001"/>
      </geometry>
      <material name="interbotix_black"/>
    </visual>
    <collision>
      <origin rpy="0 0 1.57079632679" xyz="0 0 0"/>
      <geometry>
        <mesh filename="package://interbotix_descriptions/meshes/meshes_vx300s/VXSA-300-M-3-UA.stl" scale="0.001 0.001 0.001"/>
      </geometry>
    </collision>
    <inertial>
      <origin rpy="0 0 1.57079632679" xyz="0.0206949000 0.0000000004 0.2264590000"/>
      <mass value="0.792592"/>
      <inertia ixx="0.0089250000" ixy="0.0000000000" ixz="0.0000000000" iyy="0.0089370000" iyz="0.0012010000" izz="0.0009357000"/>
    </inertial>
  </link>
  <joint name="elbow" type="revolute">
    <axis xyz="0 1 0"/>
    <limit effort="100" lower="-1.60570291183" upper="1.76278254451" velocity="3.14159265359"/>
    <origin rpy="3.14159265359 0 0" xyz="0.05955 0 0.3"/>
    <parent link="/upper_arm_link"/>
    <child link="/upper_forearm_link"/>
  </joint>
  <transmission name="trans_elbow">
    <type>transmission_interface/SimpleTransmission</type>
    <joint name="elbow">
      <hardwareInterface>hardware_interface/EffortJointInterface</hardwareInterface>
    </joint>
    <actuator name="elbow_motor">
      <mechanicalReduction>1</mechanicalReduction>
    </actuator>
  </transmission>
  <link name="/upper_forearm_link">
    <visual>
      <origin rpy="0 0 0" xyz="0 0 0"/>
      <geometry>
        <mesh filename="package://interbotix_descriptions/meshes/meshes_vx300s/VXSA-300-M-4-UF.stl" scale="0.001 0.001 0.001"/>
      </geometry>
      <material name="interbotix_black"/>
    </visual>
    <collision>
      <origin rpy="0 0 0" xyz="0 0 0"/>
      <geometry>
        <mesh filename="package://interbotix_descriptions/meshes/meshes_vx300s/VXSA-300-M-4-UF.stl" scale="0.001 0.001 0.001"/>
      </geometry>
    </collision>
    <inertial>
      <origin rpy="0 0 0" xyz="0.105723 0 0"/>
      <mass value="0.322228"/>
      <inertia ixx="0.0001524000" ixy="-0.0000188300" ixz="-0.0000084064" iyy="0.0013420000" iyz="0.0000012564" izz="0.0014410000"/>
    </inertial>
  </link>
  <joint name="forearm_roll" type="revolute">
    <axis xyz="1 0 0"/>
    <limit effort="100" lower="-3.14159265359" upper="3.14159265359" velocity="3.14159265359"/>
    <origin rpy="0 0 0" xyz="0.2 0 0"/>
    <parent link="/upper_forearm_link"/>
    <child link="/lower_forearm_link"/>
  </joint>
  <transmission name="trans_forearm_roll">
    <type>transmission_interface/SimpleTransmission</type>
    <joint name="forearm_roll">
      <hardwareInterface>hardware_interface/EffortJointInterface</hardwareInterface>
    </joint>
    <actuator name="forearm_roll_motor">
      <mechanicalReduction>1</mechanicalReduction>
    </actuator>
  </transmission>
  <link name="/lower_forearm_link">
    <visual>
      <origin rpy="0 0 0" xyz="0 0 0"/>
      <geometry>
        <mesh filename="package://interbotix_descriptions/meshes/meshes_vx300s/VXSA-300-M-5-LF.stl" scale="0.001 0.001 0.001"/>
      </geometry>
      <material name="interbotix_black"/>
    </visual>
    <collision>
      <origin rpy="0 0 0" xyz="0 0 0"/>
      <geometry>
        <mesh filename="package://interbotix_descriptions/meshes/meshes_vx300s/VXSA-300-M-5-LF.stl" scale="0.001 0.001 0.001"/>
      </geometry>
    </collision>
    <inertial>
      <origin rpy="0 0 0" xyz="0.0513477000 -0.0068046200 0"/>
      <mass value="0.414823"/>
      <inertia ixx="0.0001753000" ixy="-0.0000852800" ixz="0" iyy="0.0005269000" iyz="0" izz="0.0005911000"/>
    </inertial>
  </link>
  <joint name="wrist_angle" type="revolute">
    <axis xyz="0 1 0"/>
    <limit effort="100" lower="-2.26892802759" upper="1.86750229963" velocity="3.14159265359"/>
    <origin rpy="0 0 0" xyz="0.1 0 0"/>
    <parent link="/lower_forearm_link"/>
    <child link="/wrist_link"/>
  </joint>
  <transmission name="trans_wrist_angle">
    <type>transmission_interface/SimpleTransmission</type>
    <joint name="wrist_angle">
      <hardwareInterface>hardware_interface/EffortJointInterface</hardwareInterface>
    </joint>
    <actuator name="wrist_angle_motor">
      <mechanicalReduction>1</mechanicalReduction>
    </actuator>
  </transmission>
  <link name="/wrist_link">
    <visual>
      <origin rpy="0 3.14159265359 1.57079632679" xyz="0 0 0"/>
      <geometry>
        <mesh filename="package://interbotix_descriptions/meshes/meshes_vx300s/VXSA-300-M-6-Wrist.stl" scale="0.001 0.001 0.001"/>
      </geometry>
      <material name="interbotix_black"/>
    </visual>
    <collision>
      <origin rpy="0 3.14159265359 1.57079632679" xyz="0 0 0"/>
      <geometry>
        <mesh filename="package://interbotix_descriptions/meshes/meshes_vx300s/VXSA-300-M-6-Wrist.stl" scale="0.001 0.001 0.001"/>
      </geometry>
    </collision>
    <inertial>
      <origin rpy="0 3.14159265359 1.57079632679" xyz="0.0467430000 0.0000076652 -0.0105650000"/>
      <mass value="0.115395"/>
      <inertia ixx="0.0000463100" ixy="0.0000000195" ixz="0.0000000023" iyy="0.0000451400" iyz="0.0000042002" izz="0.0000527000"/>
    </inertial>
  </link>
  <joint name="wrist_rotate" type="revolute">
    <axis xyz="1 0 0"/>
    <limit effort="100" lower="-3.14159265359" upper="3.14159265359" velocity="3.14159265359"/>
    <origin rpy="0 1.570796327 0" xyz="0.09469 0 0"/>
    <parent link="/wrist_link"/>
    <child link="generative_gripper_5__cylinder"/>
  </joint>
  <transmission name="trans_wrist_rotate">
    <type>transmission_interface/SimpleTransmission</type>
    <joint name="wrist_rotate">
      <hardwareInterface>hardware_interface/EffortJointInterface</hardwareInterface>
    </joint>
    <actuator name="wrist_rotate_motor">
      <mechanicalReduction>1</mechanicalReduction>
    </actuator>
  </transmission>
  <joint name="generative_gripper_5__cylinder_long_arm_1_JOINT" type="revolute">
    <parent link="generative_gripper_5__cylinder"/>
    <child link="generative_gripper_5__long_arm_1"/>
    <origin rpy="1.5708  0  1.5708" xyz="0       0.02204  0.06274"/>
    <axis xyz="0  0  1"/>
    <limit effort="-1.0" lower="-1.79769e+308" upper="1.79769e+308" velocity="-1.0"/>
  </joint>
  <joint name="generative_gripper_5__cylinder_long_arm_2_JOINT" type="revolute">
    <parent link="generative_gripper_5__cylinder"/>
    <child link="generative_gripper_5__long_arm_2"/>
    <origin rpy="1.5708 0 -0.52369" xyz="0.01908 -0.01102  0.06274"/>
    <axis xyz="0  0  1"/>
    <limit effort="-100" lower="-1.79769e+308" upper="1.79769e+308" velocity="-1.0"/>
  </joint>
  <joint name="generative_gripper_5__cylinder_long_arm_3_JOINT" type="revolute">
    <parent link="generative_gripper_5__cylinder"/>
    <child link="generative_gripper_5__long_arm_3"/>
    <origin rpy="1.5708   0      -2.61798" xyz="-0.01908 -0.01102  0.06274"/>
    <axis xyz="0  0  1"/>
    <limit effort="-1.0" lower="-1.79769e+308" upper="1.79769e+308" velocity="-1.0"/>
  </joint>
  <joint name="generative_gripper_5__cylinder_motor_bracket_JOINT" type="fixed">
    <parent link="generative_gripper_5__cylinder"/>
    <child link="generative_gripper_5__motor_bracket"/>
    <origin rpy="1.5708  0      0" xyz="0       0      -0.02195"/>
    <axis xyz="0  0  0"/>
    <limit effort="0" lower="0" upper="0" velocity="0"/>
  </joint>
  <joint name="generative_gripper_5__cylinder_piston_head_JOINT" type="prismatic">
    <parent link="generative_gripper_5__cylinder"/>
    <child link="generative_gripper_5__piston_head"/>
    <origin rpy="0  0  0" xyz="0       0       0.06274"/>
    <axis xyz="0  0  1"/>
    <limit effort="-1.0" lower="-1.79769e+308" upper="1.79769e+308" velocity="-1.0"/>
  </joint>
  <joint name="generative_gripper_5__cylinder_short_arm_1_JOINT" type="revolute">
    <parent link="generative_gripper_5__cylinder"/>
    <child link="generative_gripper_5__short_arm_1"/>
    <origin rpy="1.5708  -0.78539  1.5708" xyz="0       0.02204  0.01274"/>
    <axis xyz="0  0  1"/>
    <limit effort="-1.0" lower="-1.79769e+308" upper="1.79769e+308" velocity="-1.0"/>
  </joint>
  <joint name="generative_gripper_5__cylinder_short_arm_2_JOINT" type="revolute">
    <parent link="generative_gripper_5__cylinder"/>
    <child link="generative_gripper_5__short_arm_2"/>
    <origin rpy="1.5708  -0.78539 -0.52359" xyz="0.01908 -0.01102  0.01274"/>
    <axis xyz="0  0  1"/>
    <limit effort="-1.0" lower="-1.79769e+308" upper="1.79769e+308" velocity="-1.0"/>
  </joint>
  <joint name="generative_gripper_5__cylinder_short_arm_3_JOINT" type="revolute">
    <parent link="generative_gripper_5__cylinder"/>
    <child link="generative_gripper_5__short_arm_3"/>
    <origin rpy="1.5708  -0.78539 -2.61798" xyz="-0.01908 -0.01102  0.01274"/>
    <axis xyz="0  0  1"/>
    <limit effort="-1.0" lower="-1.79769e+308" upper="1.79769e+308" velocity="-1.0"/>
  </joint>
  <joint name="generative_gripper_5__long_arm_1_outer_arm_1_JOINT" type="revolute">
    <parent link="generative_gripper_5__long_arm_1"/>
    <child link="generative_gripper_5__outer_arm_1"/>
    <origin rpy="3.14158000e+00   1.00000000e-05   1.57079000e+00" xyz="0.02121  0.02121  0"/>
    <axis xyz="0  0  1"/>
    <limit effort="-1.0" lower="-1.79769e+308" upper="1.79769e+308" velocity="-1.0"/>
  </joint>
  <joint name="generative_gripper_5__long_arm_2_outer_arm_2_JOINT" type="revolute">
    <parent link="generative_gripper_5__outer_arm_2"/>
    <child link="generative_gripper_5__long_arm_2"/>
    <origin rpy="-3.1415  0      1.5708" xyz="0.028787  -0.021213  0"/>
    <axis xyz="0  0  1"/>
    <limit effort="100" lower="-1.79769e+308" upper="1.79769e+308" velocity="-1.0"/>
  </joint>
  <joint name="generative_gripper_5__long_arm_2_pin_2_JOINT" type="revolute">
    <parent link="generative_gripper_5__long_arm_2"/>
    <child link="generative_gripper_5__pin_2"/>
    <origin rpy="0      0.0001  0" xyz="-0.01736  0       0"/>
    <axis xyz="0  0  1"/>
    <limit effort="-1.0" lower="-1.79769e+308" upper="1.79769e+308" velocity="-1.0"/>
  </joint>
  <joint name="generative_gripper_5__long_arm_3_outer_arm_3_JOINT" type="revolute">
    <parent link="generative_gripper_5__long_arm_3"/>
    <child link="generative_gripper_5__outer_arm_3"/>
    <origin rpy="-3.14158  0       1.57079" xyz="0.02121  0.02121  0"/>
    <axis xyz="0  0  1"/>
    <limit effort="-1.0" lower="-1.79769e+308" upper="1.79769e+308" velocity="-1.0"/>
  </joint>
  <joint name="generative_gripper_5__long_arm_3_pin_3_JOINT" type="revolute">
    <parent link="generative_gripper_5__long_arm_3"/>
    <child link="generative_gripper_5__pin_3"/>
    <origin rpy="-3.14158000e+00   1.00000000e-05   1.57079000e+00" xyz="-0.01736  0       0"/>
    <axis xyz="0  0  1"/>
    <limit effort="-1.0" lower="-1.79769e+308" upper="1.79769e+308" velocity="-1.0"/>
  </joint>
  <joint name="generative_gripper_5__pin_1_pin_1_JOINT" type="revolute">
    <parent link="generative_gripper_5__long_arm_1"/>
    <child link="generative_gripper_5__pin_1"/>
    <origin rpy="3.14158000e+00   1.00000000e-05   1.57079000e+00" xyz="-0.01736  0       0"/>
    <axis xyz="0  0  1"/>
    <limit effort="-1.0" lower="-1.79769e+308" upper="1.79769e+308" velocity="-1.0"/>
  </joint>
  <joint name="generative_gripper_5__piston_head_pin_1_JOINT" type="prismatic">
    <parent link="generative_gripper_5__piston_head"/>
    <child link="generative_gripper_5__pin_1"/>
    <origin rpy="-3.14105 -1.57079  3.14105" xyz="0       0.00467  0"/>
    <axis xyz="0  1  0"/>
    <limit effort="-1.0" lower="-1.79769e+308" upper="1.79769e+308" velocity="-1.0"/>
  </joint>
  <joint name="generative_gripper_5__piston_head_pin_2_JOINT" type="prismatic">
    <parent link="generative_gripper_5__piston_head"/>
    <child link="generative_gripper_5__pin_2"/>
    <origin rpy="1.5708   0      -0.52359" xyz="0.00404 -0.00233  0"/>
    <axis xyz="1  0  0"/>
    <limit effort="-1.0" lower="-1.79769e+308" upper="1.79769e+308" velocity="-1.0"/>
  </joint>
  <joint name="generative_gripper_5__piston_head_pin_3_JOINT" type="prismatic">
    <parent link="generative_gripper_5__piston_head"/>
    <child link="generative_gripper_5__pin_3"/>
    <origin rpy="-3.11223 -1.57079 -1.07654" xyz="-0.00404 -0.00233  0"/>
    <axis xyz="0  1  0"/>
    <limit effort="-1.0" lower="-1.79769e+308" upper="1.79769e+308" velocity="-1.0"/>
  </joint>
  <joint name="generative_gripper_5__short_arm_1_outer_arm_1_JOINT" type="revolute">
    <parent link="generative_gripper_5__short_arm_1"/>
    <child link="generative_gripper_5__outer_arm_1"/>
    <origin rpy="3.14158  0       0.78539" xyz="0.03  0    0"/>
    <axis xyz="0  0  1"/>
    <limit effort="-1.0" lower="-1.79769e+308" upper="1.79769e+308" velocity="-1.0"/>
  </joint>
  <joint name="generative_gripper_5__short_arm_2_outer_arm_2_JOINT" type="revolute">
    <parent link="generative_gripper_5__short_arm_2"/>
    <child link="generative_gripper_5__outer_arm_2"/>
    <origin rpy="3.14157  0       0.7854" xyz="0.03  0    0"/>
    <axis xyz="0  0  1"/>
    <limit effort="-1.0" lower="-1.79769e+308" upper="1.79769e+308" velocity="-1.0"/>
  </joint>
  <joint name="generative_gripper_5__short_arm_3_outer_arm_3_JOINT" type="revolute">
    <parent link="generative_gripper_5__short_arm_3"/>
    <child link="generative_gripper_5__outer_arm_3"/>
    <origin rpy="-3.14158  0       0.78539" xyz="0.03  0    0"/>
    <axis xyz="0  0  1"/>
    <limit effort="-1.0" lower="-1.79769e+308" upper="1.79769e+308" velocity="-1.0"/>
  </joint>
  <link name="generative_gripper_5__cylinder">
    <inertial>
      <mass value="1"/>
      <origin rpy="0  0  0" xyz="0  0  0"/>
      <inertia ixx="0.166667" ixy="0" ixz="0" iyy="0.166667" iyz="0" izz="0.166667"/>
    </inertial>
    <collision name="generative_gripper_5__collision">
      <origin rpy="0  0  0" xyz="0     0     0.035"/>
      <geometry>
        <cylinder length="0.067741" radius="0.027084"/>
      </geometry>
    </collision>
    <visual name="generative_gripper_5__visual">
      <origin rpy="0  0  0" xyz="0       0       0.06274"/>
      <geometry>
        <mesh filename="package://interbotix_descriptions/meshes/meshes_vx300s_gripper/cylinder.stl" scale="1 1 1"/>
      </geometry>
    </visual>
  </link>
  <link name="generative_gripper_5__long_arm_1">
    <inertial>
      <mass value="1"/>
      <origin rpy="0  0  0" xyz="0  0  0"/>
      <inertia ixx="0.166667" ixy="0" ixz="0" iyy="0.166667" iyz="0" izz="0.166667"/>
    </inertial>
    <visual name="generative_gripper_5__visual">
      <origin rpy="0  0  0" xyz="0  0  0"/>
      <geometry>
        <mesh filename="package://interbotix_descriptions/meshes/meshes_vx300s_gripper/long_arm.stl" scale="1 1 1"/>
      </geometry>
    </visual>
  </link>
  <link name="generative_gripper_5__long_arm_2">
    <inertial>
      <mass value="1"/>
      <origin rpy="0  0  0" xyz="0  0  0"/>
      <inertia ixx="0.166667" ixy="0" ixz="0" iyy="0.166667" iyz="0" izz="0.166667"/>
    </inertial>
    <visual name="generative_gripper_5__visual">
      <origin rpy="0  0  0" xyz="0  0  0"/>
      <geometry>
        <mesh filename="package://interbotix_descriptions/meshes/meshes_vx300s_gripper/long_arm.stl" scale="1 1 1"/>
      </geometry>
    </visual>
  </link>
  <link name="generative_gripper_5__long_arm_3">
    <inertial>
      <mass value="1"/>
      <origin rpy="0  0  0" xyz="0  0  0"/>
      <inertia ixx="0.166667" ixy="0" ixz="0" iyy="0.166667" iyz="0" izz="0.166667"/>
    </inertial>
    <visual name="generative_gripper_5__visual">
      <origin rpy="0  0  0" xyz="0  0  0"/>
      <geometry>
        <mesh filename="package://interbotix_descriptions/meshes/meshes_vx300s_gripper/long_arm.stl" scale="1 1 1"/>
      </geometry>
    </visual>
  </link>
  <link name="generative_gripper_5__motor_bracket">
    <inertial>
      <mass value="1"/>
      <origin rpy="0  0  0" xyz="0  0  0"/>
      <inertia ixx="0.166667" ixy="0" ixz="0" iyy="0.166667" iyz="0" izz="0.166667"/>
    </inertial>
    <collision name="generative_gripper_5__collision_1">
      <origin rpy="1.5708  0      0" xyz="0    0.01  0"/>
      <geometry>
        <cylinder length="0.02495" radius="0.026552"/>
      </geometry>
    </collision>
    <visual name="generative_gripper_5__visual">
      <origin rpy="0  0  0" xyz="0  0  0"/>
      <geometry>
        <mesh filename="package://interbotix_descriptions/meshes/meshes_vx300s_gripper/motor_bracket.stl" scale="1 1 1"/>
      </geometry>
    </visual>
  </link>
  <link name="generative_gripper_5__outer_arm_1">
    <inertial>
      <mass value="1"/>
      <origin rpy="0  0  0" xyz="0  0  0"/>
      <inertia ixx="0.166667" ixy="0" ixz="0" iyy="0.166667" iyz="0" izz="0.166667"/>
    </inertial>
    <collision name="generative_gripper_5__collision">
      <origin rpy="0  0  0" xyz="0  0  0"/>
      <geometry>
        <mesh filename="package://interbotix_descriptions/meshes/meshes_vx300s_gripper/outer_arm_collisional.stl" scale="1 1 1"/>
      </geometry>
    </collision>
    <visual name="generative_gripper_5__visual">
      <origin rpy="0  0  0" xyz="0  0  0"/>
      <geometry>
        <mesh filename="package://interbotix_descriptions/meshes/meshes_vx300s_gripper/outer_arm.stl" scale="1 1 1"/>
      </geometry>
    </visual>
  </link>
  <link name="generative_gripper_5__outer_arm_2">
    <inertial>
      <mass value="1"/>
      <origin rpy="0  0  0" xyz="0  0  0"/>
      <inertia ixx="0.166667" ixy="0" ixz="0" iyy="0.166667" iyz="0" izz="0.166667"/>
    </inertial>
    <collision name="generative_gripper_5__collision">
      <origin rpy="0  0  0" xyz="0  0  0"/>
      <geometry>
        <mesh filename="package://interbotix_descriptions/meshes/meshes_vx300s_gripper/outer_arm_collisional.stl" scale="1 1 1"/>
      </geometry>
    </collision>
    <visual name="generative_gripper_5__visual">
      <origin rpy="0  0  0" xyz="0  0  0"/>
      <geometry>
        <mesh filename="package://interbotix_descriptions/meshes/meshes_vx300s_gripper/outer_arm.stl" scale="1 1 1"/>
      </geometry>
    </visual>
  </link>
  <link name="generative_gripper_5__outer_arm_3">
    <inertial>
      <mass value="1"/>
      <origin rpy="0  0  0" xyz="0  0  0"/>
      <inertia ixx="0.166667" ixy="0" ixz="0" iyy="0.166667" iyz="0" izz="0.166667"/>
    </inertial>
    <collision name="generative_gripper_5__collision">
      <origin rpy="0  0  0" xyz="0  0  0"/>
      <geometry>
        <mesh filename="package://interbotix_descriptions/meshes/meshes_vx300s_gripper/outer_arm_collisional.stl" scale="1 1 1"/>
      </geometry>
    </collision>
    <visual name="generative_gripper_5__visual">
      <origin rpy="0  0  0" xyz="0  0  0"/>
      <geometry>
        <mesh filename="package://interbotix_descriptions/meshes/meshes_vx300s_gripper/outer_arm.stl" scale="1 1 1"/>
      </geometry>
    </visual>
  </link>
  <link name="generative_gripper_5__pin_1">
    <inertial>
      <mass value="1"/>
      <origin rpy="0  0  0" xyz="0  0  0"/>
      <inertia ixx="0.166667" ixy="0" ixz="0" iyy="0.166667" iyz="0" izz="0.166667"/>
    </inertial>
    <collision name="generative_gripper_5__collision">
      <origin rpy="0  0  0" xyz="0  0  0"/>
      <geometry>
        <mesh filename="package://interbotix_descriptions/meshes/meshes_vx300s_gripper/pin.stl" scale="1 1 1"/>
      </geometry>
    </collision>
    <visual name="generative_gripper_5__visual">
      <origin rpy="0  0  0" xyz="0  0  0"/>
      <geometry>
        <mesh filename="package://interbotix_descriptions/meshes/meshes_vx300s_gripper/pin.stl" scale="1 1 1"/>
      </geometry>
    </visual>
  </link>
  <link name="generative_gripper_5__pin_2">
    <inertial>
      <mass value="1"/>
      <origin rpy="0  0  0" xyz="0  0  0"/>
      <inertia ixx="0.166667" ixy="0" ixz="0" iyy="0.166667" iyz="0" izz="0.166667"/>
    </inertial>
    <visual name="generative_gripper_5__visual">
      <origin rpy="0  0  0" xyz="0  0  0"/>
      <geometry>
        <mesh filename="package://interbotix_descriptions/meshes/meshes_vx300s_gripper/pin.stl" scale="1 1 1"/>
      </geometry>
    </visual>
  </link>
  <link name="generative_gripper_5__pin_3">
    <inertial>
      <mass value="1"/>
      <origin rpy="0  0  0" xyz="0  0  0"/>
      <inertia ixx="0.166667" ixy="0" ixz="0" iyy="0.166667" iyz="0" izz="0.166667"/>
    </inertial>
    <visual name="generative_gripper_5__visual">
      <origin rpy="0  0  0" xyz="0  0  0"/>
      <geometry>
        <mesh filename="package://interbotix_descriptions/meshes/meshes_vx300s_gripper/pin.stl" scale="1 1 1"/>
      </geometry>
    </visual>
  </link>
  <link name="generative_gripper_5__piston_head">
    <inertial>
      <mass value="1"/>
      <origin rpy="0  0  0" xyz="0  0  0"/>
      <inertia ixx="0.166667" ixy="0" ixz="0" iyy="0.166667" iyz="0" izz="0.166667"/>
    </inertial>
    <visual name="generative_gripper_5__visual">
      <origin rpy="0  0  0" xyz="0  0  0"/>
      <geometry>
        <mesh filename="package://interbotix_descriptions/meshes/meshes_vx300s_gripper/piston_head.stl" scale="1 1 1"/>
      </geometry>
    </visual>
  </link>
  <link name="generative_gripper_5__short_arm_1">
    <inertial>
      <mass value="1"/>
      <origin rpy="0  0  0" xyz="0  0  0"/>
      <inertia ixx="0.166667" ixy="0" ixz="0" iyy="0.166667" iyz="0" izz="0.166667"/>
    </inertial>
    <visual name="generative_gripper_5__visual">
      <origin rpy="0  0  0" xyz="0  0  0"/>
      <geometry>
        <mesh filename="package://interbotix_descriptions/meshes/meshes_vx300s_gripper/short_arm.stl" scale="1 1 1"/>
      </geometry>
    </visual>
  </link>
  <link name="generative_gripper_5__short_arm_2">
    <inertial>
      <mass value="1"/>
      <origin rpy="0  0  0" xyz="0  0  0"/>
      <inertia ixx="0.166667" ixy="0" ixz="0" iyy="0.166667" iyz="0" izz="0.166667"/>
    </inertial>
    <visual name="generative_gripper_5__visual">
      <origin rpy="0  0  0" xyz="0  0  0"/>
      <geometry>
        <mesh filename="package://interbotix_descriptions/meshes/meshes_vx300s_gripper/short_arm.stl" scale="1 1 1"/>
      </geometry>
    </visual>
  </link>
  <link name="generative_gripper_5__short_arm_3">
    <inertial>
      <mass value="1"/>
      <origin rpy="0  0  0" xyz="0  0  0"/>
      <inertia ixx="0.166667" ixy="0" ixz="0" iyy="0.166667" iyz="0" izz="0.166667"/>
    </inertial>
    <visual name="generative_gripper_5__visual">
      <origin rpy="0  0  0" xyz="0  0  0"/>
      <geometry>
        <mesh filename="package://interbotix_descriptions/meshes/meshes_vx300s_gripper/short_arm.stl" scale="1 1 1"/>
      </geometry>
    </visual>
  </link>
  <!-- If the default gripper bar is being used, then also add the gripper bar -->
</robot>
